Workbook

Sheet ReadME
B1: S2. Supporting Information
B3: Auditory and cognitive contributions to recognition of degraded speech in noise: Individual differences among older adults
B4: Daniel Fogerty and Judy R. Dubno
B6: Primary Data | C6: TAB | D6: Notes
B7: Auditory Variables | C7: AuditoryVariables | D7: Audiogram, Psychoacoustic Speech Modulation, Speech Glimpsing
B8: Cognitive Variables | C8: CognitiveVariables | D8: Cognitive results from BTACT and visual modality testing
B9: Predictor & Outcome Measures (including demographics) | C9: Predictors&Outcomes | D9: Predictor Measures and SRT values from Datasets #1-3
B11: Analysis Results | C11: TAB | D11: Notes
B12: Spectrally reduced speech (D1SR) | C12: Dominance_D1_SR | D12: Dataset from: Fogerty D, Ahlstrom JB, Dubno JR. 2023. doi:10.1121/10.0023323. PMID:38031479.
B13: Noise-masked speech (D2NM) | C13: Dominance_D2_NM | D13: Dataset from: Fogerty D, Ahlstrom JB, Dubno JR. 2024. doi:10.1121/10.0028006. PMID:38696731. (Experiment 1)
B14: Spectrally reduced and noise-masked speech (D3SR+NM) | C14: Dominance_D3_SR+NM | D14: Dataset from: Fogerty D, Ahlstrom JB, Dubno JR. 2024. doi:10.1121/10.0028006. PMID:38696731. (Experiment 2)
B15: Overall PCA & Generalization | C15: Overall PCA & Generalization
B17: Summary Overall Dominance Plots | C17: Dominance Summary

Sheet AuditoryVariables
C1: Audiogram (dB HL) | L1: Speech Modulation Detection/Interference (k) | Q1: Speech Recognition in Noise
A2: SUBJ_ID | B2: HearGroup | C2: 250 Hz | D2: 500 Hz | E2: 1000 Hz | F2: 2000 Hz | G2: 3000 Hz | H2: 4000 Hz | I2: 6000 Hz | J2: 8000 Hz | L2: MD_Low | M2: MD_High | N2: MDI_Low | O2: MDI_High | Q2: SSN | R2: SMN | S2: Glimpsing (SMN-SSN)
A3: S01 | B3: ONH | C3: 5 | D3: 5 | E3: 5 | F3: 10 | G3: 10 | H3: 10 | I3: 5 | J3: 15 | L3: 0.17 | M3: 0.16 | N3: 0.58 | O3: 0.37 | Q3: 0.66 | R3: 0.84 | S3: 0.18
A4: S02 | B4: ONH | C4: 10 | D4: 15 | E4: 15 | F4: 5 | G4: 5 | H4: 10 | I4: 15 | J4: 30 | L4: 0.31 | M4: 0.42 | N4: 0.23 | O4: 0.6 | Q4: 0.38 | R4: 0.72 | S4: 0.34
A5: S03 | B5: ONH | C5: 0 | D5: -5 | E5: 0 | F5: 0 | G5: 10 | H5: 5 | I5: 25 | J5: 25 | L5: 0.11 | M5: 0.33 | N5: 0.15 | O5: 0.27 | Q5: 0.44 | R5: 0.74 | S5: 0.3
A6: S04 | B6: ONH | C6: 10 | D6: 10 | E6: 5 | F6: 10 | G6: 15 | H6: 25 | I6: 40 | J6: 55 | L6: 0.15 | M6: 0.19 | N6: 0.18 | O6: 0.72 | Q6: 0.32 | R6: 0.52 | S6: 0.2
A7: S05 | B7: ONH | C7: 5 | D7: 5 | E7: 15 | F7: 15 | G7: 0 | H7: 15 | I7: 20 | J7: 20 | L7: 0.23 | M7: 0.19 | N7: 0.46 | O7: 0.75 | Q7: 0.4 | R7: 0.78 | S7: 0.38
A8: S06 | B8: ONH | C8: 15 | D8: 20 | E8: 10 | F8: 10 | G8: 15 | H8: 20 | I8: 35 | J8: 55 | L8: 0.37 | M8: 0.14 | N8: 0.25 | O8: 0.33 | Q8: 0.46 | R8: 0.84 | S8: 0.38
A9: S07 | B9: ONH | C9: 20 | D9: 15 | E9: 15 | F9: 10 | G9: 15 | H9: 10 | I9: 45 | J9: 70 | L9: 0.18 | M9: 0.38 | N9: 0.52 | O9: 0.29 | Q9: 0.18 | R9: 0.5 | S9: 0.32
A10: S08 | B10: ONH | C10: 10 | D10: 5 | E10: 10 | F10: 20 | G10: 5 | H10: 25 | I10: 25 | J10: 70 | L10: 0.29 | M10: 0.15 | N10: 0.38 | O10: 0.38 | Q10: 0.16 | R10: 0.54 | S10: 0.38
A11: S09 | B11: ONH | C11: 10 | D11: 0 | E11: 0 | F11: 10 | G11: 5 | H11: 10 | I11: 10 | J11: 30 | L11: 0.17 | M11: 0.35 | N11: 0.58 | O11: 0.98 | Q11: 0.32 | R11: 0.56 | S11: 0.24
A12: S10 | B12: ONH | C12: 10 | D12: 10 | E12: 10 | F12: 15 | G12: 10 | H12: 15 | I12: 25 | J12: 30 | L12: 0.56 | M12: 0.22 | N12: 0.42 | O12: 0.84 | Q12: 0.36 | R12: 0.54 | S12: 0.18
A13: S11 | B13: ONH | C13: 5 | D13: 5 | E13: 10 | F13: 10 | G13: 0 | H13: 20 | I13: 20 | J13: 15 | L13: 0.2 | M13: 0.14 | N13: 0.32 | O13: 0.21 | Q13: 0.26 | R13: 0.62 | S13: 0.36
A14: S12 | B14: ONH | C14: 0 | D14: 5 | E14: 10 | F14: 15 | G14: 5 | H14: 10 | I14: 15 | J14: 25 | L14: 0.43 | M14: 0.23 | N14: 0.41 | O14: 0.56 | Q14: 0.4 | R14: 0.72 | S14: 0.32
... A42: S40 | B42: OHI | C42: 15 | D42: 25 | E42: 30 | F42: 35 | G42: 40 | H42: 40 | I42: 50 | J42: 55 | L42: 0.21 | M42: 0.12 | N42: 0.52 | O42: 0.67 | Q42: 0.38 | R42: 0.76 | S42: 0.38

Sheet CognitiveVariables (z-scores)
A1: SUBJ_ID | B1: HearGroup | C1: zShortRecall | D1: zNumSeries | E1: zABDS | F1: zVBDS | G1: zCategoryFluency | H1: zBackwardCounting | I1: zDelayRecall | J1: zConnections_Alternating | K1: zStroop_Mismatch
A2: S01 | B2: ONH | C2: -0.65 | D2: -1.08 | E2: 0.53 | F2: 0.55 | G2: 0.51 | H2: 0 | I2: -0.24 | J2: -0.17 | K2: -0.31
A3: S02 | B3: ONH | C3: -0.21 | D3: -0.38 | E3: 0.53 | F3: 1.2 | G3: -1.17 | H3: -1.3 | I3: -0.66 | J3: -1.05 | K3: -1.25
A4: S03 | B4: ONH | C4: 0.68 | D4: -0.38 | E4: -0.86 | F4: -0.77 | G4: -0.5 | H4: -0.96 | I4: -0.24 | J4: -0.48 | K4: -1.05
A5: S04 | B5: ONH | C5: 0.23 | D5: -1.78 | E5: -1.56 | F5: -1.42 | G5: -1.68 | H5: -1.65 | I5: -0.66 | J5: -1.82 | K5: -0.05
A6: S05 | B6: ONH | C6: 1.57 | D6: 0.32 | E6: -0.16 | F6: -1.42 | G6: -0.16 | H6: -0.96 | I6: 0.17 | J6: 0.49 | K6: -1.65
A7: S06 | B7: ONH | C7: -0.21 | D7: 0.32 | E7: 1.23 | F7: 1.2 | G7: 0.01 | H7: -0.61 | I7: -0.24 | J7: -0.95 | K7: -1.25
A8: S07 | B8: ONH | C8: -0.65 | D8: 0.32 | E8: -1.56 | F8: -0.11 | G8: -0.5 | H8: 0.61 | I8: -0.24 | J8: -0.43 | K8: -0.85
A9: S08 | B9: ONH | C9: -0.65 | D9: -0.38 | E9: -0.86 | F9: -0.11 | G9: -0.5 | H9: -0.52 | I9: -1.08 | J9: 0.13 | K9: -1.52
A10: S09 | B10: ONH | C10: -1.1 | D10: -1.78 | E10: -0.86 | F10: -0.77 | G10: -1.34 | H10: -1.39 | I10: -0.66 | J10: -1.1 | K10: -0.72
A11: S10 | B11: ONH | C11: -0.65 | D11: -2.48 | E11: -0.86 | F11: -0.77 | G11: -0.67 | H11: -1.48 | I11: -1.5 | J11: -1.67 | K11: -0.78
A12: S11 | B12: ONH | C12: 2.01 | D12: 0.32 | E12: 1.23 | F12: 1.2 | G12: 0.34 | H12: 0.7 | I12: 1.85 | J12: 0.8 | K12: 0.16
A13: S12 | B13: ONH | C13: -0.65 | D13: 0.32 | E13: 0.53 | F13: -0.11 | G13: 0.17 | H13: -0.26 | I13: -0.66 | J13: -0.23 | K13: 0.22
... A41: S40 | B41: OHI | C41: 1.57 | D41: -0.38 | E41: -0.16 | F41: 0.55 | G41: 0.34 | H41: -0.35 | I41: 1.43 | J41: -0.43 | K41: -0.25

Sheet Predictors&Outcomes
A1: Subjects | G1: Predictor Measures | O1: Outcome Measures | X1: Summary Outcomes
A2: SUBJ_ID | B2: HearGroup | C2: Age | D2: Sex | E2: MMSE | F2: PTA4 | G2: Audiogram_PCA | H2: SpeechModulation_PCA | I2: WorkingMemory_PCA | J2: EpisodicMemory_PCA | K2: Interference_PCA | L2: Vocabulary | M2: LinguisticClosure | N2: Glimpsing | O2: D1_SRT20_ESTOI | P2: D1_SRT50_ESTOI | Q2: D1_SRT80_ESTOI | R2: D2_SRT20_ESTOI | S2: D2_SRT50_ESTOI | T2: D2_SRT80_ESTOI | U2: D3_SRT20_ESTOI | V2: D3_SRT50_ESTOI | W2: D3_SRT80_ESTOI | X2: Overall_PCA (Experimental) | Y2: Generalization_PCA
A3: S01 | B3: ONH | C3: 69 | D3: F | E3: 30 | F3: 7.5 | G3: -0.13268 | H3: -0.11267 | I3: 0.49042 | J3: -0.30704 | K3: -0.35394 | L3: 1.28 | M3: -0.65302 | N3: 0.12 | O3: 0.12 | P3: 0.25 | Q3: 0.37 | R3: -0.02 | S3: 0.16 | T3: 0.35 | U3: 0.12 | V3: 0.22 | W3: 0.32 | X3: -1.38098 | Y3: 0.01731
A4: S02 | B4: ONH | C4: 70 | D4: M | E4: 30 | F4: 11.3 | G4: 0.24026 | H4: 0.30969 | I4: 0.90261 | J4: -0.66238 | K4: -1.39069 | L4: 1.51 | M4: 0.22162 | N4: 0.18 | O4: 0.14 | P4: 0.25 | Q4: 0.35 | R4: -0.09 | S4: 0.21 | T4: 0.5 | U4: 0.1 | V4: 0.2 | W4: 0.3 | X4: -1.35226 | Y4: 0.37403
A5: S03 | B5: ONH | C5: 68 | D5: F | E5: 30 | F5: 0 | G5: -0.36669 | H5: -0.6619 | I5: -0.65294 | J5: 0.45845 | K5: -0.69009 | L5: 0.94 | M5: -0.22385 | N5: 0.34 | O5: 0.19 | P5: 0.28 | Q5: 0.37 | R5: 0.19 | S5: 0.27 | T5: 0.35 | U5: 0.12 | V5: 0.22 | W5: 0.33 | X5: -0.73055 | Y5: 0.86446
A6: S04 | B6: ONH | C6: 66 | D6: F | E6: 30 | F6: 12.5 | G6: 0.53699 | H6: -0.33479 | I6: -1.57083 | J6: 0.0389 | K6: -0.65487 | L6: -0.2 | M6: 0.37625 | N6: 0.3 | O6: 0.25 | P6: 0.39 | Q6: 0.53 | R6: 0.16 | S6: 0.36 | T6: 0.57 | U6: 0.21 | V6: 0.35 | W6: 0.48 | X6: 1.30423 | Y6: -1.69598
A7: S05 | B7: ONH | C7: 67 | D7: F | E7: 30 | F7: 12.5 | G7: 0.11568 | H7: 0.24015 | I7: -0.68511 | J7: 1.11669 | K7: -0.59189 | L7: 0.49 | M7: 2.01655 | N7: 0.2 | O7: 0.19 | P7: 0.28 | Q7: 0.38 | R7: 0.1 | S7: 0.24 | T7: 0.39 | U7: 0.14 | V7: 0.23 | W7: 0.32 | X7: -0.75963 | Y7: 0.34139
A8: S06 | B8: ONH | C8: 74 | D8: F | E8: 30 | F8: 15 | G8: 0.74005 | H8: -0.16129 | I8: 1.38658 | J8: -0.28888 | K8: -1.39766 | L8: 1.17 | M8: 1.03174 | N8: 0.38 | O8: 0.2 | P8: 0.29 | Q8: 0.39 | R8: 0.17 | S8: 0.27 | T8: 0.37 | U8: 0.19 | V8: 0.25 | W8: 0.32 | X8: -0.4104 | Y8: -0.02839
A9: S07 | B9: ONH | C9: 71 | D9: F | E9: 28 | F9: 12.5 | G9: 0.87368 | H9: 0.07088 | I9: -0.08761 | J9: -0.19403 | K9: -0.33477 | L9: 0.49 | M9: -0.767 | N9: 0.38 | O9: 0.18 | P9: 0.33 | Q9: 0.48 | R9: 0.18 | S9: 0.38 | T9: 0.58 | U9: 0.19 | V9: 0.3 | W9: 0.42 | X9: 0.63138 | Y9: -0.57859
A10: S08 | B10: ONH | C10: 70 | D10: F | E10: 30 | F10: 15 | G10: 0.5389 | H10: -0.11179 | I10: 0.03076 | J10: -0.64984 | K10: -0.54284 | L10: 0.15 | M10: 0.4585 | N10: 0.32 | O10: 0.18 | P10: 0.29 | Q10: 0.4 | R10: 0.2 | S10: 0.29 | T10: 0.39 | U10: 0.15 | V10: 0.26 | W10: 0.36 | X10: -0.33222 | Y10: -0.28146
A11: S09 | B11: ONH | C11: 66 | D11: F | E11: 30 | F11: 5 | G11: -0.12964 | H11: 0.69112 | I11: -0.77405 | J11: -0.65977 | K11: -0.68713 | L11: -2.02 | M11: 2.67647 | N11: 0.38 | O11: 0.16 | P11: 0.31 | Q11: 0.46 | R11: 0.06 | S11: 0.26 | T11: 0.46 | U11: 0.14 | V11: 0.26 | W11: 0.37 | X11: -0.31151 | Y11: 0.03039
A12: S10 | B12: ONH | C12: 66 | D12: F | E12: 27 | F12: 12.5 | G12: 0.3403 | H12: 1.05037 | I12: -0.77209 | J12: -0.65031 | K12: -1.08122 | L12: 0.15 | M12: -0.16989 | N12: 0.24 | O12: 0.15 | P12: 0.29 | Q12: 0.42 | R12: 0.11 | S12: 0.28 | T12: 0.44 | U12: 0.16 | V12: 0.27 | W12: 0.39 | X12: -0.28397 | Y12: -0.32237
A13: S11 | B13: ONH | C13: 61 | D13: F | E13: 30 | F13: 11.3 | G13: 0.01242 | H13: -0.55648 | I13: 0.61076 | J13: 1.5324 | K13: -0.0145 | L13: 1.85 | M13: -0.79639 | N13: 0.18 | O13: 0.19 | P13: 0.29 | Q13: 0.39 | R13: 0.14 | S13: 0.25 | T13: 0.36 | U13: 0.15 | V13: 0.24 | W13: 0.34 | X13: -0.56997 | Y13: 0.2681
A14: S12 | B14: ONH | C14: 69 | D14: F | E14: 29 | F14: 10 | G14: -0.02406 | H14: 0.51327 | I14: 0.4692 | J14: -0.53302 | K14: 0.09011 | L14: 0.72 | M14: -0.40421 | N14: 0.36 | O14: 0.17 | P14: 0.27 | Q14: 0.38 | R14: 0.1 | S14: 0.25 | T14: 0.4 | U14: 0.13 | V14: 0.25 | W14: 0.36 | X14: -0.66518 | Y14: -0.12434
... A42: S40 | B42: OHI | C42: 60 | D42: F | E42: 30 | F42: 32.5 | G42: 1.72811 | H42: 0.10523 | I42: -0.22872 | J42: 1.49666 | K42: -0.63205 | L42: 1.06 | M42: 0.47418 | N42: 0.38 | O42: 0.2 | P42: 0.31 | Q42: 0.41 | R42: 0.13 | S42: 0.31 | T42: 0.48 | U42: 0.15 | V42: 0.26 | W42: 0.37 | X42: -0.12604 | Y42: 0.69312

Sheet Dominance_D1-SR
B1: ONH (Older Normal Hearing) | M1: OHI (Older Hearing Impaired)
A2: D1_SR - SRT20 | F2: Total | G2: Audio | H2: WM | I2: Vocab | J2: Glimpse | L2: D1_SR - SRT20 | Q2: Total | R2: Audio | S2: WM | T2: Vocab | U2: Glimpse
E3: k=0 avg | G3: =F4 -> 0.183184 | H3: =F5 -> 0.1369 | I3: =F6 -> 0.215296 | J3: =F7 -> 0.088 | P3: k=0 avg | R3: =Q4 -> 0.4096 | S3: =Q5 -> 0.447561 | T3: =Q6 -> 0.358801 | U3: =Q7 -> 0.549081
D4: Audio | F4: 0.183184 | H4: =F9-F4 -> 0.152057 | I4: =F10-F4 -> 0.169652 | J4: =F11-F4 -> 0.066816 | O4: Audio | Q4: 0.4096 | S4: =Q9-Q4 -> 0.164964 | T4: =Q10-Q4 -> 0.200361 | U4: =Q11-Q4 -> 0.301049
D5: WM | F5: 0.1369 | G5: =F9-F5 -> 0.198341 | I5: =F12-F5 -> 0.081189 | J5: =F13-F5 -> 0.0311 | O5: WM | Q5: 0.447561 | R5: =Q9-Q5 -> 0.127003 | T5: =Q12-Q5 -> 0.034075 | U5: =Q13-Q5 -> 0.280048
D6: Vocab | F6: 0.215296 | G6: =F10-F6 -> 0.13754 | H6: =F12-F6 -> 0.002793 | J6: =F14-F6 -> 0.013704 | O6: Vocab | Q6: 0.358801 | R6: =Q10-Q6 -> 0.25116 | S6: =Q12-Q6 -> 0.122835 | U6: =Q14-Q6 -> 0.268463
D7: Glimpse | F7: 0.088 | G7: =F11-F7 -> 0.162 | H7: =F13-F7 -> 0.08 | I7: =F14-F7 -> 0.141 | O7: Glimpse | Q7: 0.549081 | R7: =Q11-Q7 -> 0.161568 | S7: =Q13-Q7 -> 0.178528 | T7: =Q14-Q7 -> 0.078183
E8: k=1 avg | G8: =AVERAGE(G4:G7) -> 0.16596033 | H8: =AVERAGE(H4:H7) -> 0.078283333 | I8: =AVERAGE(I4:I7) -> 0.13061367 | J8: =AVERAGE(J4:J7) -> 0.037206667 | P8: k=1 avg | R8: =AVERAGE(R4:R7) -> 0.17991033 | S8: =AVERAGE(S4:S7) -> 0.15544233 | T8: =AVERAGE(T4:T7) -> 0.10420633 | U8: =AVERAGE(U4:U7) -> 0.28318667
C9: Audio | D9: WM | F9: 0.335241 | I9: =F16-F9 -> 0.034423 | J9: =F17-F9 -> 0.015759 | N9: Audio | O9: WM | Q9: 0.574564 | T9: =Q16-Q9 -> 0.054285 | U9: =Q17-Q9 -> 0.215757
C10: Audio | D10: Vocab | F10: 0.352836 | H10: =F16-F10 -> 0.016828 | J10: =F18-F10 -> 0.009164 | N10: Audio | O10: Vocab | Q10: 0.609961 | S10: =Q16-Q10 -> 0.018888 | U10: =Q18-Q10 -> 0.157415
C11: Audio | D11: Glimpse | F11: 0.25 | H11: =F17-F11 -> 0.101 | I11: =F18-F11 -> 0.112 | N11: Audio | O11: Glimpse | Q11: 0.710649 | S11: =Q17-Q11 -> 0.079672 | T11: =Q18-Q11 -> 0.056727
C12: WM | D12: Vocab | F12: 0.218089 | G12: =F16-F12 -> 0.151575 | J12: =F19-F12 -> 0.012911 | N12: WM | O12: Vocab | Q12: 0.481636 | R12: =Q16-Q12 -> 0.147213 | U12: =Q19-Q12 -> 0.245973
C13: WM | D13: Glimpse | F13: 0.168 | G13: =F17-F13 -> 0.183 | I13: =F19-F13 -> 0.063 | N13: WM | O13: Glimpse | Q13: 0.727609 | R13: =Q17-Q13 -> 0.062712 | T13: =Q19-Q13 -> 0
C14: Vocab | D14: Glimpse | F14: 0.229 | G14: =F18-F14 -> 0.133 | H14: =F19-F14 -> 0.002 | N14: Vocab | O14: Glimpse | Q14: 0.627264 | R14: =Q18-Q14 -> 0.140112 | S14: =Q19-Q14 -> 0.100345
E15: k=2 avg | G15: =AVERAGE(G11:G14) -> 0.15585833 | H15: =AVERAGE(H11:H14) -> 0.0515 | I15: =AVERAGE(I11:I14) -> 0.0875 | J15: =AVERAGE(J11:J14) -> 0.012911 | P15: k=2 avg | R15: =AVERAGE(R11:R14) -> 0.116679 | S15: =AVERAGE(S11:S14) -> 0.0900085 | T15: =AVERAGE(T11:T14) -> 0.0283635 | U15: =AVERAGE(U11:U14) -> 0.245973
B16: Audio | C16: WM | D16: Vocab | F16: 0.369664 | J16: =F21-F16 -> 0.007336 | M16: Audio | N16: WM | O16: Vocab | Q16: 0.628849 | U16: =Q21-Q16 -> 0.165032
B17: Audio | C17: WM | D17: Glimpse | F17: 0.351 | I17: =F21-F17 -> 0.026 | M17: Audio | N17: WM | O17: Glimpse | Q17: 0.790321 | T17: =Q21-Q17 -> 0.00356
B18: Audio | C18: Vocab | D18: Glimpse | F18: 0.362 | H18: =F21-F18 -> 0.015 | M18: Audio | N18: Vocab | O18: Glimpse | Q18: 0.767376 | S18: =Q21-Q18 -> 0.026505
B19: WM | C19: Vocab | D19: Glimpse | F19: 0.231 | G19: =F21-F19 -> 0.146 | M19: WM | N19: Vocab | O19: Glimpse | Q19: 0.727609 | R19: =Q21-Q19 -> 0.066272
E20: k=3 avg | G20: =AVERAGE(G16:G19) -> 0.146 | H20: =AVERAGE(H16:H19) -> 0.015 | I20: =AVERAGE(I16:I19) -> 0.026 | J20: =AVERAGE(J16:J19) -> 0.007336 | P20: k=3 avg | R20: =AVERAGE(R16:R19) -> 0.066272 | S20: =AVERAGE(S16:S19) -> 0.026505 | T20: =AVERAGE(T16:T19) -> 0.00356 | U20: =AVERAGE(U16:U19) -> 0.165032
B21: Audio | C21: WM | D21: Vocab | E21: Glimpse | F21: 0.377 | M21: Audio | N21: WM | O21: Vocab | P21: Glimpse | Q21: 0.793881
E22: Overall Avg | G22: =AVERAGE(G3,G8,G15,G20) -> 0.16275067 | H22: =AVERAGE(H3,H8,H15,H20) -> 0.070420833 | I22: =AVERAGE(I3,I8,I15,I20) -> 0.11485242 | J22: =AVERAGE(J3,J8,J15,J20) -> 0.036363417 | P22: Overall Avg | R22: =AVERAGE(R3,R8,R15,R20) -> 0.19311533 | S22: =AVERAGE(S3,S8,S15,S20) -> 0.17987921 | T22: =AVERAGE(T3,T8,T15,T20) -> 0.12373271 | U22: =AVERAGE(U3,U8,U15,U20) -> 0.31081817
A26: D1_SR - SRT50 | F26: Total | G26: Audio | H26: WM | I26: Vocab | J26: Glimpse | L26: D1_SR - SRT50 | Q26: Total | R26: Audio | S26: WM | T26: Vocab | U26: Glimpse
E27: k=0 avg | G27: =F28 -> 0.266256 | H27: =F29 -> 0.241081 | I27: =F30 -> 0.410881 | J27: =F31 -> 0.20801399 | P27: k=0 avg | R27: =Q28 -> 0.316969 | S27: =Q29 -> 0.341056 | T27: =Q30 -> 0.306916 | U27: =Q31 -> 0.544644
D28: Audio | F28: 0.266256 | H28: =F33-F28 -> 0.265185 | I28: =F34-F28 -> 0.334369 | J28: =F35-F28 -> 0.167744 | O28: Audio | Q28: 0.316969 | S28: =Q33-Q28 -> 0.123927 | T28: =Q34-Q28 -> 0.17724 | U28: =Q35-Q28 -> 0.331056
D29: WM | F29: 0.241081 | G29: =F33-F29 -> 0.29036 | I29: =F36-F29 -> 0.172368 | J29: =F37-F29 -> 0.091919 | O29: WM | Q29: 0.341056 | R29: =Q33-Q29 -> 0.09984 | T29: =Q36-Q29 -> 0.040868 | U29: =Q37-Q29 -> 0.313425
D30: Vocab | F30: 0.410881 | G30: =F34-F30 -> 0.189744 | H30: =F36-F30 -> 0.002568 | J30: =F38-F30 -> 0.044119 | O30: Vocab | Q30: 0.306916 | R30: =Q34-Q30 -> 0.187293 | S30: =Q36-Q30 -> 0.075008 | U30: =Q38-Q30 -> 0.290613
D31: Glimpse | F31: 0.20801399 | G31: =F35-F31 -> 0.22598601 | H31: =F37-F31 -> 0.12498601 | I31: =F38-F31 -> 0.24698601 | O31: Glimpse | Q31: 0.544644 | R31: =Q35-Q31 -> 0.103381 | S31: =Q37-Q31 -> 0.109837 | T31: =Q38-Q31 -> 0.052885
E32: k=1 avg | G32: =AVERAGE(G28:G31) -> 0.23536334 | H32: =AVERAGE(H28:H31) -> 0.130913 | I32: =AVERAGE(I28:I31) -> 0.251241 | J32: =AVERAGE(J28:J31) -> 0.10126067 | P32: k=1 avg | R32: =AVERAGE(R28:R31) -> 0.13017133 | S32: =AVERAGE(S28:S31) -> 0.102924 | T32: =AVERAGE(T28:T31) -> 0.090331 | U32: =AVERAGE(U28:U31) -> 0.311698
C33: Audio | D33: WM | F33: 0.531441 | I33: =F40-F33 -> 0.087928 | J33: =F41-F33 -> 0.058559 | N33: Audio | O33: WM | Q33: 0.440896 | T33: =Q40-Q33 -> 0.061785 | U33: =Q41-Q33 -> 0.25466
C34: Audio | D34: Vocab | F34: 0.600625 | H34: =F40-F34 -> 0.018744 | J34: =F42-F34 -> 0.035375 | N34: Audio | O34: Vocab | Q34: 0.494209 | S34: =Q40-Q34 -> 0.008472 | U34: =Q42-Q34 -> 0.193032
C35: Audio | D35: Glimpse | F35: 0.434 | H35: =F41-F35 -> 0.156 | I35: =F42-F35 -> 0.202 | N35: Audio | O35: Glimpse | Q35: 0.648025 | S35: =Q41-Q35 -> 0.047531 | T35: =Q42-Q35 -> 0.039216
C36: WM | D36: Vocab | F36: 0.413449 | G36: =F40-F36 -> 0.20592 | J36: =F43-F36 -> 0.041551 | N36: WM | O36: Vocab | Q36: 0.381924 | R36: =Q40-Q36 -> 0.120757 | U36: =Q43-Q36 -> 0.272557
C37: WM | D37: Glimpse | F37: 0.333 | G37: =F41-F37 -> 0.257 | I37: =F43-F37 -> 0.122 | N37: WM | O37: Glimpse | Q37: 0.654481 | R37: =Q41-Q37 -> 0.041075 | T37: =Q43-Q37 -> 0
C38: Vocab | D38: Glimpse | F38: 0.455 | G38: =F42-F38 -> 0.181 | H38: =F43-F38 -> 0 | N38: Vocab | O38: Glimpse | Q38: 0.597529 | R38: =Q42-Q38 -> 0.089712 | S38: =Q43-Q38 -> 0.056952
E39: k=2 avg | G39: =AVERAGE(G35:G38) -> 0.21464 | H39: =AVERAGE(H35:H38) -> 0.078 | I39: =AVERAGE(I35:I38) -> 0.162 | J39: =AVERAGE(J35:J38) -> 0.041551 | P39: k=2 avg | R39: =AVERAGE(R35:R38) -> 0.083848 | S39: =AVERAGE(S35:S38) -> 0.0522415 | T39: =AVERAGE(T35:T38) -> 0.019608 | U39: =AVERAGE(U35:U38) -> 0.272557
B40: Audio | C40: WM | D40: Vocab | F40: 0.619369 | J40: =F45-F40 -> 0.031631 | M40: Audio | N40: WM | O40: Vocab | Q40: 0.502681 | U40: =Q45-Q40 -> 0.197888
B41: Audio | C41: WM | D41: Glimpse | F41: 0.59 | I41: =F45-F41 -> 0.061 | M41: Audio | N41: WM | O41: Glimpse | Q41: 0.695556 | T41: =Q45-Q41 -> 0.005013
B42: Audio | C42: Vocab | D42: Glimpse | F42: 0.636 | H42: =F45-F42 -> 0.015 | M42: Audio | N42: Vocab | O42: Glimpse | Q42: 0.687241 | S42: =Q45-Q42 -> 0.013328
B43: WM | C43: Vocab | D43: Glimpse | F43: 0.455 | G43: =F45-F43 -> 0.196 | M43: WM | N43: Vocab | O43: Glimpse | Q43: 0.654481 | R43: =Q45-Q43 -> 0.046088
...

Sheet Dominance_D2-NM
B1: ONH (Older Normal Hearing) | M1: OHI (Older Hearing Impaired)
A2: D2_NM - SRT20 | F2: Total | G2: Audio | H2: WM | I2: Vocab | J2: Glimpse | L2: D2_NM - SRT20 | Q2: Total | R2: Audio | S2: WM | T2: Vocab | U2: Glimpse
E3: k=0 avg | G3: =F4 -> 0.266256 | H3: =F5 -> 0.105625 | I3: =F6 -> 0.196249 | J3: =F7 -> 0.032 | P3: k=0 avg | R3: =Q4 -> 0.553536 | S3: =Q5 -> 0.373321 | T3: =Q6 -> 0.140625 | U3: =Q7 -> 0.454276
D4: Audio | F4: 0.266256 | H4: =F9-F4 -> 0.121873 | I4: =F10-F4 -> 0.142065 | J4: =F11-F4 -> 0.016744 | O4: Audio | Q4: 0.553536 | S4: =Q9-Q4 -> 0.078489 | T4: =Q10-Q4 -> 0.034753 | U4: =Q11-Q4 -> 0.19296
D5: WM | F5: 0.105625 | G5: =F9-F5 -> 0.282504 | I5: =F12-F5 -> 0.090624 | J5: =F13-F5 -> 0.005375 | O5: WM | Q5: 0.373321 | R5: =Q9-Q5 -> 0.258704 | T5: =Q12-Q5 -> 0.006135 | U5: =Q13-Q5 -> 0.231963
D6: Vocab | F6: 0.196249 | G6: =F10-F6 -> 0.212072 | H6: =F12-F6 -> 0 | J6: =F14-F6 -> -0.000249 | O6: Vocab | Q6: 0.140625 | R6: =Q10-Q6 -> 0.447664 | S6: =Q12-Q6 -> 0.238831 | U6: =Q14-Q6 -> 0.317704
D7: Glimpse | F7: 0.032 | G7: =F11-F7 -> 0.251 | H7: =F13-F7 -> 0.079 | I7: =F14-F7 -> 0.164 | O7: Glimpse | Q7: 0.454276 | R7: =Q11-Q7 -> 0.29222 | S7: =Q13-Q7 -> 0.151008 | T7: =Q14-Q7 -> 0.004053
E8: k=1 avg | G8: =AVERAGE(G4:G7) -> 0.24852533 | H8: =AVERAGE(H4:H7) -> 0.066957667 | I8: =AVERAGE(I4:I7) -> 0.13222967 | J8: =AVERAGE(J4:J7) -> 0.00729 | P8: k=1 avg | R8: =AVERAGE(R4:R7) -> 0.33286267 | S8: =AVERAGE(S4:S7) -> 0.15610933 | T8: =AVERAGE(T4:T7) -> 0.014980333 | U8: =AVERAGE(U4:U7) -> 0.24754233
C9: Audio | D9: WM | F9: 0.388129 | I9: =F16-F9 -> 0.031775 | J9: =F17-F9 -> -0.000129 | N9: Audio | O9: WM | Q9: 0.632025 | T9: =Q16-Q9 -> 0 | U9: =Q17-Q9 -> 0.145899
C10: Audio | D10: Vocab | F10: 0.408321 | H10: =F16-F10 -> 0.011583 | J10: =F18-F10 -> 0.000679 | N10: Audio | O10: Vocab | Q10: 0.588289 | S10: =Q16-Q10 -> 0.043736 | U10: =Q18-Q10 -> 0.158207
C11: Audio | D11: Glimpse | F11: 0.283 | H11: =F17-F11 -> 0.105 | I11: =F18-F11 -> 0.126 | N11: Audio | O11: Glimpse | Q11: 0.746496 | S11: =Q17-Q11 -> 0.031428 | T11: =Q18-Q11 -> 0
C12: WM | D12: Vocab | F12: 0.196249 | G12: =F16-F12 -> 0.223655 | J12: =F19-F12 -> -0.000249 | N12: WM | O12: Vocab | Q12: 0.379456 | R12: =Q16-Q12 -> 0.252569 | U12: =Q19-Q12 -> 0.284769
C13: WM | D13: Glimpse | F13: 0.111 | G13: =F17-F13 -> 0.277 | I13: =F19-F13 -> 0.085 | N13: WM | O13: Glimpse | Q13: 0.605284 | R13: =Q17-Q13 -> 0.17264 | T13: =Q19-Q13 -> 0.058941
C14: Vocab | D14: Glimpse | F14: 0.196 | G14: =F18-F14 -> 0.213 | H14: =F19-F14 -> 0 | N14: Vocab | O14: Glimpse | Q14: 0.458329 | R14: =Q18-Q14 -> 0.288167 | S14: =Q19-Q14 -> 0.205896
E15: k=2 avg | G15: =AVERAGE(G11:G14) -> 0.237885 | H15: =AVERAGE(H11:H14) -> 0.0525 | I15: =AVERAGE(I11:I14) -> 0.1055 | J15: =AVERAGE(J11:J14) -> -0.000249 | P15: k=2 avg | R15: =AVERAGE(R11:R14) -> 0.237792 | S15: =AVERAGE(S11:S14) -> 0.118662 | T15: =AVERAGE(T11:T14) -> 0.0294705 | U15: =AVERAGE(U11:U14) -> 0.284769
B16: Audio | C16: WM | D16: Vocab | F16: 0.419904 | J16: =F21-F16 -> 0.001096 | M16: Audio | N16: WM | O16: Vocab | Q16: 0.632025 | U16: =Q21-Q16 -> 0.169
B17: Audio | C17: WM | D17: Glimpse | F17: 0.388 | I17: =F21-F17 -> 0.033 | M17: Audio | N17: WM | O17: Glimpse | Q17: 0.777924 | T17: =Q21-Q17 -> 0.023101
B18: Audio | C18: Vocab | D18: Glimpse | F18: 0.409 | H18: =F21-F18 -> 0.012 | M18: Audio | N18: Vocab | O18: Glimpse | Q18: 0.746496 | S18: =Q21-Q18 -> 0.054529
B19: WM | C19: Vocab | D19: Glimpse | F19: 0.196 | G19: =F21-F19 -> 0.225 | M19: WM | N19: Vocab | O19: Glimpse | Q19: 0.664225 | R19: =Q21-Q19 -> 0.1368
E20: k=3 avg | G20: =AVERAGE(G16:G19) -> 0.225 | H20: =AVERAGE(H16:H19) -> 0.012 | I20: =AVERAGE(I16:I19) -> 0.033 | J20: =AVERAGE(J16:J19) -> 0.001096 | P20: k=3 avg | R20: =AVERAGE(R16:R19) -> 0.1368 | S20: =AVERAGE(S16:S19) -> 0.054529 | T20: =AVERAGE(T16:T19) -> 0.023101 | U20: =AVERAGE(U16:U19) -> 0.169
B21: Audio | C21: WM | D21: Vocab | E21: Glimpse | F21: 0.421 | M21: Audio | N21: WM | O21: Vocab | P21: Glimpse | Q21: 0.801025
E22: Overall Avg | G22: =AVERAGE(G3,G8,G15,G20) -> 0.24441658 | H22: =AVERAGE(H3,H8,H15,H20) -> 0.059270667 | I22: =AVERAGE(I3,I8,I15,I20) -> 0.11674467 | J22: =AVERAGE(J3,J8,J15,J20) -> 0.01003425 | P22: Overall Avg | R22: =AVERAGE(R3,R8,R15,R20) -> 0.31524767 | S22: =AVERAGE(S3,S8,S15,S20) -> 0.17565533 | T22: =AVERAGE(T3,T8,T15,T20) -> 0.052044208 | U22: =AVERAGE(U3,U8,U15,U20) -> 0.28889683
A26: D2_NM - SRT50 | F26: Total | G26: Audio | H26: WM | I26: Vocab | J26: Glimpse | L26: D2_NM - SRT50 | Q26: Total | R26: Audio | S26: WM | T26: Vocab | U26: Glimpse
E27: k=0 avg | G27: =F28 -> 0.364816 | H27: =F29 -> 0.194481 | I27: =F30 -> 0.374544 | J27: =F31 -> 0.153 | P27: k=0 avg | R27: =Q28 -> 0.674041 | S27: =Q29 -> 0.418609 | T27: =Q30 -> 0.228484 | U27: =Q31 -> 0.494209
D28: Audio | F28: 0.364816 | H28: =F33-F28 -> 0.220409 | I28: =F34-F28 -> 0.288048 | J28: =F35-F28 -> 0.113184 | O28: Audio | Q28: 0.674041 | S28: =Q33-Q28 -> 0.077648 | T28: =Q34-Q28 -> 0.074184 | U28: =Q35-Q28 -> 0.194583
D29: WM | F29: 0.194481 | G29: =F33-F29 -> 0.390744 | I29: =F36-F29 -> 0.180063 | J29: =F37-F29 -> 0.063519 | O29: WM | Q29: 0.418609 | R29: =Q33-Q29 -> 0.33308 | T29: =Q36-Q29 -> 0.001295 | U29: =Q37-Q29 -> 0.247247
D30: Vocab | F30: 0.374544 | G30: =F34-F30 -> 0.27832 | H30: =F36-F30 -> 0 | J30: =F38-F30 -> 0.022456 | O30: Vocab | Q30: 0.228484 | R30: =Q34-Q30 -> 0.519741 | S30: =Q36-Q30 -> 0.19142 | U30: =Q38-Q30 -> 0.2928
D31: Glimpse | F31: 0.153 | G31: =F35-F31 -> 0.325 | H31: =F37-F31 -> 0.105 | I31: =F38-F31 -> 0.244 | O31: Glimpse | Q31: 0.494209 | R31: =Q35-Q31 -> 0.374415 | S31: =Q37-Q31 -> 0.171647 | T31: =Q38-Q31 -> 0.027075
E32: k=1 avg | G32: =AVERAGE(G28:G31) -> 0.33135467 | H32: =AVERAGE(H28:H31) -> 0.10846967 | I32: =AVERAGE(I28:I31) -> 0.23737033 | J32: =AVERAGE(J28:J31) -> 0.066386333 | P32: k=1 avg | R32: =AVERAGE(R28:R31) -> 0.40907867 | S32: =AVERAGE(S28:S31) -> 0.146905 | T32: =AVERAGE(T28:T31) -> 0.034184667 | U32: =AVERAGE(U28:U31) -> 0.24487667
C33: Audio | D33: WM | F33: 0.585225 | I33: =F40-F33 -> 0.080631 | J33: =F41-F33 -> 0.032775 | N33: Audio | O33: WM | Q33: 0.751689 | T33: =Q40-Q33 -> 0.012187 | U33: =Q41-Q33 -> 0.147015
C34: Audio | D34: Vocab | F34: 0.652864 | H34: =F40-F34 -> 0.012992 | J34: =F42-F34 -> 0.016136 | N34: Audio | O34: Vocab | Q34: 0.748225 | S34: =Q40-Q34 -> 0.015651 | U34: =Q42-Q34 -> 0.129744
C35: Audio | D35: Glimpse | F35: 0.478 | H35: =F41-F35 -> 0.14 | I35: =F42-F35 -> 0.191 | N35: Audio | O35: Glimpse | Q35: 0.868624 | S35: =Q41-Q35 -> 0.03008 | T35: =Q42-Q35 -> 0.009345
C36: WM | D36: Vocab | F36: 0.374544 | G36: =F40-F36 -> 0.291312 | J36: =F43-F36 -> 0.022456 | N36: WM | O36: Vocab | Q36: 0.419904 | R36: =Q40-Q36 -> 0.343972 | U36: =Q43-Q36 -> 0.264025
C37: WM | D37: Glimpse | F37: 0.258 | G37: =F41-F37 -> 0.36 | I37: =F43-F37 -> 0.139 | N37: WM | O37: Glimpse | Q37: 0.665856 | R37: =Q41-Q37 -> 0.232848 | T37: =Q43-Q37 -> 0.018073
C38: Vocab | D38: Glimpse | F38: 0.397 | G38: =F42-F38 -> 0.272 | H38: =F43-F38 -> 0 | N38: Vocab | O38: Glimpse | Q38: 0.521284 | R38: =Q42-Q38 -> 0.356685 | S38: =Q43-Q38 -> 0.162645
E39: k=2 avg | G39: =AVERAGE(G35:G38) -> 0.30777067 | H39: =AVERAGE(H35:H38) -> 0.07 | I39: =AVERAGE(I35:I38) -> 0.165 | J39: =AVERAGE(J35:J38) -> 0.022456 | P39: k=2 avg | R39: =AVERAGE(R35:R38) -> 0.31116833 | S39: =AVERAGE(S35:S38) -> 0.0963625 | T39: =AVERAGE(T35:T38) -> 0.013709 | U39: =AVERAGE(U35:U38) -> 0.264025
B40: Audio | C40: WM | D40: Vocab | F40: 0.665856 | J40: =F45-F40 -> 0.014144 | M40: Audio | N40: WM | O40: Vocab | Q40: 0.763876 | U40: =Q45-Q40 -> 0.136725
B41: Audio | C41: WM | D41: Glimpse | F41: 0.618 | I41: =F45-F41 -> 0.062 | M41: Audio | N41: WM | O41: Glimpse | Q41: 0.898704 | T41: =Q45-Q41 -> 0.001897
B42: Audio | C42: Vocab | D42: Glimpse | F42: 0.669 | H42: =F45-F42 -> 0.011 | M42: Audio | N42: Vocab | O42: Glimpse | Q42: 0.877969 | S42: =Q45-Q42 -> 0.022632
B43: WM | C43: Vocab | D43: Glimpse | F43: 0.397 | G43: =F45-F43 -> 0.283 | M43: WM | N43: Vocab | O43: Glimpse | Q43: 0.683929 | R43: =Q45-Q43 -> 0.216672
...

Sheet Dominance_D3-SR+NM
B1: ONH (Older Normal Hearing) | M1: OHI (Older Hearing Impaired)
A2: D3_SR+NM - SRT20 | F2: Total | G2: Audio | H2: WM | I2: Vocab | J2: Glimpse | L2: D3_SR+NM - SRT20 | Q2: Total | R2: Audio | S2: WM | T2: Vocab | U2: Glimpse
E3: k=0 avg | G3: =F4 -> 0.410881 | H3: =F5 -> 0.1849 | I3: =F6 -> 0.316969 | J3: =F7 -> 0.207 | P3: k=0 avg | R3: =Q4 -> 0.524176 | S3: =Q5 -> 0.3364 | T3: =Q6 -> 0.198025 | U3: =Q7 -> 0.414736
D4: Audio | F4: 0.410881 | H4: =F9-F4 -> 0.21164 | I4: =F10-F4 -> 0.233928 | J4: =F11-F4 -> 0.158119 | O4: Audio | Q4: 0.524176 | S4: =Q9-Q4 -> 0.065648 | T4: =Q10-Q4 -> 0.070265 | U4: =Q11-Q4 -> 0.17138
D5: WM | F5: 0.1849 | G5: =F9-F5 -> 0.437621 | I5: =F12-F5 -> 0.134325 | J5: =F13-F5 -> 0.1051 | O5: WM | Q5: 0.3364 | R5: =Q9-Q5 -> 0.253424 | T5: =Q12-Q5 -> 0.003489 | U5: =Q13-Q5 -> 0.212681
D6: Vocab | F6: 0.316969 | G6: =F10-F6 -> 0.32784 | H6: =F12-F6 -> 0.002256 | J6: =F14-F6 -> 0.059031 | O6: Vocab | Q6: 0.198025 | R6: =Q10-Q6 -> 0.396416 | S6: =Q12-Q6 -> 0.141864 | U6: =Q14-Q6 -> 0.242871
D7: Glimpse | F7: 0.207 | G7: =F11-F7 -> 0.362 | H7: =F13-F7 -> 0.083 | I7: =F14-F7 -> 0.169 | O7: Glimpse | Q7: 0.414736 | R7: =Q11-Q7 -> 0.28082 | S7: =Q13-Q7 -> 0.134345 | T7: =Q14-Q7 -> 0.02616
E8: k=1 avg | G8: =AVERAGE(G4:G7) -> 0.37582033 | H8: =AVERAGE(H4:H7) -> 0.098965333 | I8: =AVERAGE(I4:I7) -> 0.17908433 | J8: =AVERAGE(J4:J7) -> 0.10741667 | P8: k=1 avg | R8: =AVERAGE(R4:R7) -> 0.31022 | S8: =AVERAGE(S4:S7) -> 0.11395233 | T8: =AVERAGE(T4:T7) -> 0.033304667 | U8: =AVERAGE(U4:U7) -> 0.20897733
C9: Audio | D9: WM | F9: 0.622521 | I9: =F16-F9 -> 0.046603 | J9: =F17-F9 -> 0.062479 | N9: Audio | O9: WM | Q9: 0.589824 | T9: =Q16-Q9 -> 0.01546 | U9: =Q17-Q9 -> 0.130977
C10: Audio | D10: Vocab | F10: 0.644809 | H10: =F16-F10 -> 0.024315 | J10: =F18-F10 -> 0.047191 | N10: Audio | O10: Vocab | Q10: 0.594441 | S10: =Q16-Q10 -> 0.010843 | U10: =Q18-Q10 -> 0.111159
C11: Audio | D11: Glimpse | F11: 0.569 | H11: =F17-F11 -> 0.116 | I11: =F18-F11 -> 0.123 | N11: Audio | O11: Glimpse | Q11: 0.695556 | S11: =Q17-Q11 -> 0.025245 | T11: =Q18-Q11 -> 0.010044
C12: WM | D12: Vocab | F12: 0.319225 | G12: =F16-F12 -> 0.349899 | J12: =F19-F12 -> 0.057775 | N12: WM | O12: Vocab | Q12: 0.339889 | R12: =Q16-Q12 -> 0.265395 | U12: =Q19-Q12 -> 0.219615
C13: WM | D13: Glimpse | F13: 0.29 | G13: =F17-F13 -> 0.395 | I13: =F19-F13 -> 0.087 | N13: WM | O13: Glimpse | Q13: 0.549081 | R13: =Q17-Q13 -> 0.17172 | T13: =Q19-Q13 -> 0.010423
C14: Vocab | D14: Glimpse | F14: 0.376 | G14: =F18-F14 -> 0.316 | H14: =F19-F14 -> 0.001 | N14: Vocab | O14: Glimpse | Q14: 0.440896 | R14: =Q18-Q14 -> 0.264704 | S14: =Q19-Q14 -> 0.118608
E15: k=2 avg | G15: =AVERAGE(G11:G14) -> 0.353633 | H15: =AVERAGE(H11:H14) -> 0.0585 | I15: =AVERAGE(I11:I14) -> 0.105 | J15: =AVERAGE(J11:J14) -> 0.057775 | P15: k=2 avg | R15: =AVERAGE(R11:R14) -> 0.23393967 | S15: =AVERAGE(S11:S14) -> 0.0719265 | T15: =AVERAGE(T11:T14) -> 0.0102335 | U15: =AVERAGE(U11:U14) -> 0.219615
B16: Audio | C16: WM | D16: Vocab | F16: 0.669124 | J16: =F21-F16 -> 0.041876 | M16: Audio | N16: WM | O16: Vocab | Q16: 0.605284 | U16: =Q21-Q16 -> 0.115517
B17: Audio | C17: WM | D17: Glimpse | F17: 0.685 | I17: =F21-F17 -> 0.026 | M17: Audio | N17: WM | O17: Glimpse | Q17: 0.720801 | T17: =Q21-Q17 -> 0
B18: Audio | C18: Vocab | D18: Glimpse | F18: 0.692 | H18: =F21-F18 -> 0.019 | M18: Audio | N18: Vocab | O18: Glimpse | Q18: 0.7056 | S18: =Q21-Q18 -> 0.015201
B19: WM | C19: Vocab | D19: Glimpse | F19: 0.377 | G19: =F21-F19 -> 0.334 | M19: WM | N19: Vocab | O19: Glimpse | Q19: 0.559504 | R19: =Q21-Q19 -> 0.161297
E20: k=3 avg | G20: =AVERAGE(G16:G19) -> 0.334 | H20: =AVERAGE(H16:H19) -> 0.019 | I20: =AVERAGE(I16:I19) -> 0.026 | J20: =AVERAGE(J16:J19) -> 0.041876 | P20: k=3 avg | R20: =AVERAGE(R16:R19) -> 0.161297 | S20: =AVERAGE(S16:S19) -> 0.015201 | T20: =AVERAGE(T16:T19) -> 0 | U20: =AVERAGE(U16:U19) -> 0.115517
B21: Audio | C21: WM | D21: Vocab | E21: Glimpse | F21: 0.711 | M21: Audio | N21: WM | O21: Vocab | P21: Glimpse | Q21: 0.720801
E22: Overall Avg | G22: =AVERAGE(G3,G8,G15,G20) -> 0.36858358 | H22: =AVERAGE(H3,H8,H15,H20) -> 0.090341333 | I22: =AVERAGE(I3,I8,I15,I20) -> 0.15676333 | J22: =AVERAGE(J3,J8,J15,J20) -> 0.10351692 | P22: Overall Avg | R22: =AVERAGE(R3,R8,R15,R20) -> 0.30740817 | S22: =AVERAGE(S3,S8,S15,S20) -> 0.13436996 | T22: =AVERAGE(T3,T8,T15,T20) -> 0.060390792 | U22: =AVERAGE(U3,U8,U15,U20) -> 0.23971133
A26: D3_SR+NM - SRT50 | G26: Audio | H26: WM | I26: Vocab | J26: Glimpse | L26: D3_SR+NM - SRT50 | R26: Audio | S26: WM | T26: Vocab | U26: Glimpse
E27: k=0 avg | G27: =F28 -> 0.314721 | H27: =F29 -> 0.320356 | I27: =F30 -> 0.407044 | J27: =F31 -> 0.247 | P27: k=0 avg | R27: =Q28 -> 0.570025 | S27: =Q29 -> 0.492804 | T27: =Q30 -> 0.370881 | U27: =Q31 -> 0.454276
D28: Audio | F28: 0.314721 | H28: =F33-F28 -> 0.351135 | I28: =F34-F28 -> 0.32368 | J28: =F35-F28 -> 0.200279 | O28: Audio | Q28: 0.570025 | S28: =Q33-Q28 -> 0.142311 | T28: =Q34-Q28 -> 0.181664 | U28: =Q35-Q28 -> 0.188616
D29: WM | F29: 0.320356 | G29: =F33-F29 -> 0.3455 | I29: =F36-F29 -> 0.111293 | J29: =F37-F29 -> 0.101644 | O29: WM | Q29: 0.492804 | R29: =Q33-Q29 -> 0.219532 | T29: =Q36-Q29 -> 0.027037 | U29: =Q37-Q29 -> 0.197757
D30: Vocab | F30: 0.407044 | G30: =F34-F30 -> 0.231357 | H30: =F36-F30 -> 0.024605 | J30: =F38-F30 -> 0.064956 | O30: Vocab | Q30: 0.370881 | R30: =Q34-Q30 -> 0.380808 | S30: =Q36-Q30 -> 0.14896 | U30: =Q38-Q30 -> 0.191619
D31: Glimpse | F31: 0.247 | G31: =F35-F31 -> 0.268 | H31: =F37-F31 -> 0.175 | I31: =F38-F31 -> 0.225 | O31: Glimpse | Q31: 0.454276 | R31: =Q35-Q31 -> 0.304365 | S31: =Q37-Q31 -> 0.236285 | T31: =Q38-Q31 -> 0.108224
E32: k=1 avg | G32: =AVERAGE(G28:G31) -> 0.281619 | H32: =AVERAGE(H28:H31) -> 0.18358 | I32: =AVERAGE(I28:I31) -> 0.219991 | J32: =AVERAGE(J28:J31) -> 0.122293 | P32: k=1 avg | R32: =AVERAGE(R28:R31) -> 0.30156833 | S32: =AVERAGE(S28:S31) -> 0.175852 | T32: =AVERAGE(T28:T31) -> 0.10564167 | U32: =AVERAGE(U28:U31) -> 0.192664
C33: Audio | D33: WM | F33: 0.665856 | I33: =F40-F33 -> 0.039744 | J33: =F41-F33 -> 0.064144 | N33: Audio | O33: WM | Q33: 0.712336 | T33: =Q40-Q33 -> 0.053289 | U33: =Q41-Q33 -> 0.124889
C34: Audio | D34: Vocab | F34: 0.638401 | H34: =F40-F34 -> 0.067199 | J34: =F42-F34 -> 0.055599 | N34: Audio | O34: Vocab | Q34: 0.751689 | S34: =Q40-Q34 -> 0.013936 | U34: =Q42-Q34 -> 0.078232
C35: Audio | D35: Glimpse | F35: 0.515 | H35: =F41-F35 -> 0.215 | I35: =F42-F35 -> 0.179 | N35: Audio | O35: Glimpse | Q35: 0.758641 | S35: =Q41-Q35 -> 0.078584 | T35: =Q42-Q35 -> 0.07128
C36: WM | D36: Vocab | F36: 0.431649 | G36: =F40-F36 -> 0.273951 | J36: =F43-F36 -> 0.058351 | N36: WM | O36: Vocab | Q36: 0.519841 | R36: =Q40-Q36 -> 0.245784 | U36: =Q43-Q36 -> 0.17072
C37: WM | D37: Glimpse | F37: 0.422 | G37: =F41-F37 -> 0.308 | I37: =F43-F37 -> 0.068 | N37: WM | O37: Glimpse | Q37: 0.690561 | R37: =Q41-Q37 -> 0.146664 | T37: =Q43-Q37 -> 0
C38: Vocab | D38: Glimpse | F38: 0.472 | G38: =F42-F38 -> 0.222 | H38: =F43-F38 -> 0.018 | N38: Vocab | O38: Glimpse | Q38: 0.5625 | R38: =Q42-Q38 -> 0.267421 | S38: =Q43-Q38 -> 0.128061
E39: k=2 avg | G39: =AVERAGE(G35:G38) -> 0.26798367 | H39: =AVERAGE(H35:H38) -> 0.1165 | I39: =AVERAGE(I35:I38) -> 0.1235 | J39: =AVERAGE(J35:J38) -> 0.058351 | P39: k=2 avg | R39: =AVERAGE(R35:R38) -> 0.21995633 | S39: =AVERAGE(S35:S38) -> 0.1033225 | T39: =AVERAGE(T35:T38) -> 0.03564 | U39: =AVERAGE(U35:U38) -> 0.17072
B40: Audio | C40: WM | D40: Vocab | F40: 0.7056 | J40: =F45-F40 -> 0.0444 | M40: Audio | N40: WM | O40: Vocab | Q40: 0.765625 | U40: =Q45-Q40 -> 0.084459
B41: Audio | C41: WM | D41: Glimpse | F41: 0.73 | I41: =F45-F41 -> 0.02 | M41: Audio | N41: WM | O41: Glimpse | Q41: 0.837225 | T41: =Q45-Q41 -> 0.012859
B42: Audio | C42: Vocab | D42: Glimpse | F42: 0.694 | H42: =F45-F42 -> 0.056 | M42: Audio | N42: Vocab | O42: Glimpse | Q42: 0.829921 | S42: =Q45-Q42 -> 0.020163
B43: WM | C43: Vocab | D43: Glimpse | F43: 0.49 | G43: =F45-F43 -> 0.26 | M43: WM | N43: Vocab | O43: Glimpse | Q43: 0.690561 | R43: =Q45-Q43 -> 0.159523
...

Sheet Dominance_Summary
C1: ONH | K1: OHI
B3: D1 | D3: Audiogram | E3: Working Memory | F3: Vocabulary | G3: Glimpsing | J3: D1 | L3: Audiogram | M3: Working Memory | N3: Vocabulary | O3: Glimpsing
C4: SRT20 | D4: ='Dominance_D1-SR'!G75 -> 0.16275067 | E4: ='Dominance_D1-SR'!H75 -> 0.070420833 | F4: ='Dominance_D1-SR'!I75 -> 0.11485242 | G4: ='Dominance_D1-SR'!J75 -> 0.036363417 | K4: SRT20 | L4: ='Dominance_D1-SR'!R75 -> 0.19311533 | M4: ='Dominance_D1-SR'!S75 -> 0.17987921 | N4: ='Dominance_D1-SR'!T75 -> 0.12373271 | O4: ='Dominance_D1-SR'!U75 -> 0.31081817
C5: SRT50 | D5: ='Dominance_D1-SR'!G76 -> 0.22806483 | E5: ='Dominance_D1-SR'!H76 -> 0.1162485 | F5: ='Dominance_D1-SR'!I76 -> 0.2212805 | G5: ='Dominance_D1-SR'!J76 -> 0.095614163 | K5: SRT50 | L5: ='Dominance_D1-SR'!R76 -> 0.14426908 | M5: ='Dominance_D1-SR'!S76 -> 0.12738738 | N5: ='Dominance_D1-SR'!T76 -> 0.105467 | O5: ='Dominance_D1-SR'!U76 -> 0.33169675
C6: SRT80 | D6: ='Dominance_D1-SR'!G77 -> 0.25902608 | E6: ='Dominance_D1-SR'!H77 -> 0.11862658 | F6: ='Dominance_D1-SR'!I77 -> 0.23979758 | G6: ='Dominance_D1-SR'!J77 -> 0.092053917 | K6: SRT80 | L6: ='Dominance_D1-SR'!R77 -> 0.063424417 | M6: ='Dominance_D1-SR'!S77 -> 0.082179917 | N6: ='Dominance_D1-SR'!T77 -> 0.086037875 | O6: ='Dominance_D1-SR'!U77 -> 0.27783083
B8: D2 | D8: Audiogram | E8: Working Memory | F8: Vocabulary | G8: Glimpsing | J8: D2 | L8: Audiogram | M8: Working Memory | N8: Vocabulary | O8: Glimpsing
C9: SRT20 | D9: ='Dominance_D2-NM'!G75 -> 0.24441658 | E9: ='Dominance_D2-NM'!H75 -> 0.059270667 | F9: ='Dominance_D2-NM'!I75 -> 0.11674467 | G9: ='Dominance_D2-NM'!J75 -> 0.01003425 | K9: SRT20 | L9: ='Dominance_D2-NM'!R75 -> 0.31524767 | M9: ='Dominance_D2-NM'!S75 -> 0.17565533 | N9: ='Dominance_D2-NM'!T75 -> 0.052044208 | O9: ='Dominance_D2-NM'!U75 -> 0.28889683
C10: SRT50 | D10: ='Dominance_D2-NM'!G76 -> 0.32173533 | E10: ='Dominance_D2-NM'!H76 -> 0.095987667 | F10: ='Dominance_D2-NM'!I76 -> 0.20972858 | G10: ='Dominance_D2-NM'!J76 -> 0.063996583 | K10: SRT50 | L10: ='Dominance_D2-NM'!R76 -> 0.40274 | M10: ='Dominance_D2-NM'!S76 -> 0.17112712 | N10: ='Dominance_D2-NM'!T76 -> 0.069568667 | O10: ='Dominance_D2-NM'!U76 -> 0.28495892
C11: SRT80 | D11: ='Dominance_D2-NM'!G77 -> 0.20683333 | E11: ='Dominance_D2-NM'!H77 -> 0.08383225 | F11: ='Dominance_D2-NM'!I77 -> 0.18161233 | G11: ='Dominance_D2-NM'!J77 -> 0.11611558 | K11: SRT80 | L11: ='Dominance_D2-NM'!R77 -> 0.41097275 | M11: ='Dominance_D2-NM'!S77 -> 0.14209783 | N11: ='Dominance_D2-NM'!T77 -> 0.095626625 | O11: ='Dominance_D2-NM'!U77 -> 0.24400833
B13: D3 | D13: Audiogram | E13: Working Memory | F13: Vocabulary | G13: Glimpsing | J13: D3 | L13: Audiogram | M13: Working Memory | N13: Vocabulary | O13: Glimpsing
C14: SRT20 | D14: ='Dominance_D3-SR+NM'!G75 -> 0.36858358 | E14: ='Dominance_D3-SR+NM'!H75 -> 0.090341333 | F14: ='Dominance_D3-SR+NM'!I75 -> 0.15676333 | G14: ='Dominance_D3-SR+NM'!J75 -> 0.10351692 | K14: SRT20 | L14: ='Dominance_D3-SR+NM'!R75 -> 0.30740817 | M14: ='Dominance_D3-SR+NM'!S75 -> 0.13436996 | N14: ='Dominance_D3-SR+NM'!T75 -> 0.060390792 | O14: ='Dominance_D3-SR+NM'!U75 -> 0.23971133
C15: SRT50 | D15: ='Dominance_D3-SR+NM'!G76 -> 0.28108092 | E15: ='Dominance_D3-SR+NM'!H76 -> 0.169109 | F15: ='Dominance_D3-SR+NM'!I76 -> 0.19263375 | G15: ='Dominance_D3-SR+NM'!J76 -> 0.118011 | K15: SRT50 | L15: ='Dominance_D3-SR+NM'!R76 -> 0.31276817 | M15: ='Dominance_D3-SR+NM'!S76 -> 0.19803537 | N15: ='Dominance_D3-SR+NM'!T76 -> 0.13125542 | O15: ='Dominance_D3-SR+NM'!U76 -> 0.22552975
C16: SRT80 | D16: ='Dominance_D3-SR+NM'!G77 -> 0.15482392 | E16: ='Dominance_D3-SR+NM'!H77 -> 0.20975167 | F16: ='Dominance_D3-SR+NM'!I77 -> 0.17722942 | G16: ='Dominance_D3-SR+NM'!J77 -> 0.10152967 | K16: SRT80 | L16: ='Dominance_D3-SR+NM'!R77 -> 0.23602467 | M16: ='Dominance_D3-SR+NM'!S77 -> 0.20835325 | N16: ='Dominance_D3-SR+NM'!T77 -> 0.18567092 | O16: ='Dominance_D3-SR+NM'!U77 -> 0.15874258
C18: WM | D18: ONH | I18: OHI
D19: D1 | E19: D2 | F19: D3 | G19: MEAN | I19: D1 | J19: D2 | K19: D3 | L19: MEAN
C20: SRT20 | D20: =E4 -> 0.070420833 | E20: =E9 -> 0.059270667 | F20: =E14 -> 0.090341333 | G20: =AVERAGE(D20:F20) -> 0.073344278 | I20: =M4 -> 0.17987921 | J20: =M9 -> 0.17565533 | K20: =M14 -> 0.13436996 | L20: =AVERAGE(I20:K20) -> 0.1633015
C21: SRT50 | D21: =E5 -> 0.1162485 | E21: =E10 -> 0.095987667 | F21: =E15 -> 0.169109 | G21: =AVERAGE(D21:F21) -> 0.12711506 | I21: =M5 -> 0.12738738 | J21: =M10 -> 0.17112712 | K21: =M15 -> 0.19803537 | L21: =AVERAGE(I21:K21) -> 0.16551662
C22: SRT80 | D22: =E6 -> 0.11862658 | E22: =E11 -> 0.08383225 | F22: =E16 -> 0.20975167 | G22: =AVERAGE(D22:F22) -> 0.1374035 | I22: =M6 -> 0.082179917 | J22: =M11 -> 0.14209783 | K22: =M16 -> 0.20835325 | L22: =AVERAGE(I22:K22) -> 0.14421033
C24: VOCAB | D24: ONH | I24: OHI
D25: D1 | E25: D2 | F25: D3 | I25: D1 | J25: D2 | K25: D3
C26: SRT20 | D26: =F4 -> 0.11485242 | E26: =F9 -> 0.11674467 | F26: =F14 -> 0.15676333 | G26: =AVERAGE(D26:F26) -> 0.12945347 | I26: =N4 -> 0.12373271 | J26: =N9 -> 0.052044208 | K26: =N14 -> 0.060390792 | L26: =AVERAGE(I26:K26) -> 0.078722569
C27: SRT50 | D27: =F5 -> 0.2212805 | E27: =F10 -> 0.20972858 | F27: =F15 -> 0.19263375 | G27: =AVERAGE(D27:F27) -> 0.20788094 | I27: =N5 -> 0.105467 | J27: =N10 -> 0.069568667 | K27: =N15 -> 0.13125542 | L27: =AVERAGE(I27:K27) -> 0.10209703
C28: SRT80 | D28: =F6 -> 0.23979758 | E28: =F11 -> 0.18161233 | F28: =F16 -> 0.17722942 | G28: =AVERAGE(D28:F28) -> 0.19954644 | I28: =N6 -> 0.086037875 | J28: =N11 -> 0.095626625 | K28: =N16 -> 0.18567092 | L28: =AVERAGE(I28:K28) -> 0.12244514
C30: Glimpse | D30: ONH | I30: OHI
D31: D1 | E31: D2 | F31: D3 | I31: D1 | J31: D2 | K31: D3
C32: SRT20 | D32: =G4 -> 0.036363417 | E32: =G9 -> 0.01003425 | F32: =G14 -> 0.10351692 | G32: =AVERAGE(D32:F32) -> 0.049971528 | I32: =O4 -> 0.31081817 | J32: =O9 -> 0.28889683 | K32: =O14 -> 0.23971133 | L32: =AVERAGE(I32:K32) -> 0.27980878
C33: SRT50 | D33: =G5 -> 0.095614163 | E33: =G10 -> 0.063996583 | F33: =G15 -> 0.118011 | G33: =AVERAGE(D33:F33) -> 0.092540582 | I33: =O5 -> 0.33169675 | J33: =O10 -> 0.28495892 | K33: =O15 -> 0.22552975 | L33: =AVERAGE(I33:K33) -> 0.28072847
C34: SRT80 | D34: =G6 -> 0.092053917 | E34: =G11 -> 0.11611558 | F34: =G16 -> 0.10152967 | G34: =AVERAGE(D34:F34) -> 0.10323306 | I34: =O6 -> 0.27783083 | J34: =O11 -> 0.24400833 | K34: =O16 -> 0.15874258 | L34: =AVERAGE(I34:K34) -> 0.22686058
C36: Audio | D36: ONH | I36: OHI
D37: D1 | E37: D2 | F37: D3 | I37: D1 | J37: D2 | K37: D3
C38: SRT20 | D38: =D4 -> 0.16275067 | E38: =D9 -> 0.24441658 | F38: =D14 -> 0.36858358 | G38: =AVERAGE(D38:F38) -> 0.25858361 | I38: =L4 -> 0.19311533 | J38: =L9 -> 0.31524767 | K38: =L14 -> 0.30740817 | L38: =AVERAGE(I38:K38) -> 0.27192372
C39: SRT50 | D39: =D5 -> 0.22806483 | E39: =D10 -> 0.32173533 | F39: =D15 -> 0.28108092 | G39: =AVERAGE(D39:F39) -> 0.27696036 | I39: =L5 -> 0.14426908 | J39: =L10 -> 0.40274 | K39: =L15 -> 0.31276817 | L39: =AVERAGE(I39:K39) -> 0.28659242
C40: SRT80 | D40: =D6 -> 0.25902608 | E40: =D11 -> 0.20683333 | F40: =D16 -> 0.15482392 | G40: =AVERAGE(D40:F40) -> 0.20689444 | I40: =L6 -> 0.063424417 | J40: =L11 -> 0.41097275 | K40: =L16 -> 0.23602467 | L40: =AVERAGE(I40:K40) -> 0.23680728

Sheet Overall PCA & Generalization
B1: ONH (Older Normal Hearing) | M1: OHI (Older Hearing Impaired)
A2: 3Datasets_OverallPCA | F2: Total | G2: Audio | H2: WM | I2: Vocab | J2: Glimpse | L2: 3Datasets_OverallPCA | Q2: Total | R2: Audio | S2: WM | T2: Vocab | U2: Glimpse
E3: k=0 avg | G3: =F4 -> 0.336 | H3: =F5 -> 0.261 | I3: =F6 -> 0.415 | J3: =F7 -> 0.205 | P3: k=0 avg | R3: =Q4 -> 0.548 | S3: =Q5 -> 0.458 | T3: =Q6 -> 0.332 | U3: =Q7 -> 0.546
D4: Audio | F4: 0.336 | H4: =F9-F4 -> 0.29 | I4: =F10-F4 -> 0.328 | J4: =F11-F4 -> 0.161 | O4: Audio | Q4: 0.548 | S4: =Q9-Q4 -> 0.128 | T4: =Q10-Q4 -> 0.157 | U4: =Q11-Q4 -> 0.26
D5: WM | F5: 0.261 | G5: =F9-F5 -> 0.365 | I5: =F12-F5 -> 0.159 | J5: =F13-F5 -> 0.085 | O5: WM | Q5: 0.458 | R5: =Q9-Q5 -> 0.218 | T5: =Q12-Q5 -> 0.021 | U5: =Q13-Q5 -> 0.275
D6: Vocab | F6: 0.415 | G6: =F10-F6 -> 0.249 | H6: =F12-F6 -> 0.005 | J6: =F14-F6 -> 0.041 | O6: Vocab | Q6: 0.332 | R6: =Q10-Q6 -> 0.373 | S6: =Q12-Q6 -> 0.147 | U6: =Q14-Q6 -> 0.28
D7: Glimpse | F7: 0.205 | G7: =F11-F7 -> 0.292 | H7: =F13-F7 -> 0.141 | I7: =F14-F7 -> 0.251 | O7: Glimpse | Q7: 0.546 | R7: =Q11-Q7 -> 0.262 | S7: =Q13-Q7 -> 0.187 | T7: =Q14-Q7 -> 0.066
E8: k=1 avg | G8: =AVERAGE(G4:G7) -> 0.302 | H8: =AVERAGE(H4:H7) -> 0.14533333 | I8: =AVERAGE(I4:I7) -> 0.246 | J8: =AVERAGE(J4:J7) -> 0.095666667 | P8: k=1 avg | R8: =AVERAGE(R4:R7) -> 0.28433333 | S8: =AVERAGE(S4:S7) -> 0.154 | T8: =AVERAGE(T4:T7) -> 0.081333333 | U8: =AVERAGE(U4:U7) -> 0.27166667
C9: Audio | D9: WM | F9: 0.626 | I9: =F16-F9 -> 0.068 | J9: =F17-F9 -> 0.049 | N9: Audio | O9: WM | Q9: 0.676 | T9: =Q16-Q9 -> 0.043 | U9: =Q17-Q9 -> 0.189
C10: Audio | D10: Vocab | F10: 0.664 | H10: =F16-F10 -> 0.03 | J10: =F18-F10 -> 0.033 | N10: Audio | O10: Vocab | Q10: 0.705 | S10: =Q16-Q10 -> 0.014 | U10: =Q18-Q10 -> 0.143
C11: Audio | D11: Glimpse | F11: 0.497 | H11: =F17-F11 -> 0.178 | I11: =F18-F11 -> 0.2 | N11: Audio | O11: Glimpse | Q11: 0.808 | S11: =Q17-Q11 -> 0.057 | T11: =Q18-Q11 -> 0.04
C12: WM | D12: Vocab | F12: 0.42 | G12: =F16-F12 -> 0.274 | J12: =F19-F12 -> 0.039 | N12: WM | O12: Vocab | Q12: 0.479 | R12: =Q16-Q12 -> 0.24 | U12: =Q19-Q12 -> 0.255
C13: WM | D13: Glimpse | F13: 0.346 | G13: =F17-F13 -> 0.329 | I13: =F19-F13 -> 0.113 | N13: WM | O13: Glimpse | Q13: 0.733 | R13: =Q17-Q13 -> 0.132 | T13: =Q19-Q13 -> 0.001
C14: Vocab | D14: Glimpse | F14: 0.456 | G14: =F18-F14 -> 0.241 | H14: =F19-F14 -> 0.003 | N14: Vocab | O14: Glimpse | Q14: 0.612 | R14: =Q18-Q14 -> 0.236 | S14: =Q19-Q14 -> 0.122
E15: k=2 avg | G15: =AVERAGE(G11:G14) -> 0.28133333 | H15: =AVERAGE(H11:H14) -> 0.0905 | I15: =AVERAGE(I11:I14) -> 0.1565 | J15: =AVERAGE(J11:J14) -> 0.039 | P15: k=2 avg | R15: =AVERAGE(R11:R14) -> 0.20266667 | S15: =AVERAGE(S11:S14) -> 0.0895 | T15: =AVERAGE(T11:T14) -> 0.0205 | U15: =AVERAGE(U11:U14) -> 0.255
B16: Audio | C16: WM | D16: Vocab | F16: 0.694 | J16: =F21-F16 -> 0.028 | M16: Audio | N16: WM | O16: Vocab | Q16: 0.719 | U16: =Q21-Q16 -> 0.149
B17: Audio | C17: WM | D17: Glimpse | F17: 0.675 | I17: =F21-F17 -> 0.047 | M17: Audio | N17: WM | O17: Glimpse | Q17: 0.865 | T17: =Q21-Q17 -> 0.003
B18: Audio | C18: Vocab | D18: Glimpse | F18: 0.697 | H18: =F21-F18 -> 0.025 | M18: Audio | N18: Vocab | O18: Glimpse | Q18: 0.848 | S18: =Q21-Q18 -> 0.02
B19: WM | C19: Vocab | D19: Glimpse | F19: 0.459 | G19: =F21-F19 -> 0.263 | M19: WM | N19: Vocab | O19: Glimpse | Q19: 0.734 | R19: =Q21-Q19 -> 0.134
E20: k=3 avg | G20: =AVERAGE(G16:G19) -> 0.263 | H20: =AVERAGE(H16:H19) -> 0.025 | I20: =AVERAGE(I16:I19) -> 0.047 | J20: =AVERAGE(J16:J19) -> 0.028 | P20: k=3 avg | R20: =AVERAGE(R16:R19) -> 0.134 | S20: =AVERAGE(S16:S19) -> 0.02 | T20: =AVERAGE(T16:T19) -> 0.003 | U20: =AVERAGE(U16:U19) -> 0.149
B21: Audio | C21: WM | D21: Vocab | E21: Glimpse | F21: 0.722 | M21: Audio | N21: WM | O21: Vocab | P21: Glimpse | Q21: 0.868
E22: Overall Avg | G22: =AVERAGE(G3,G8,G15,G20) -> 0.29558333 | H22: =AVERAGE(H3,H8,H15,H20) -> 0.13045833 | I22: =AVERAGE(I3,I8,I15,I20) -> 0.216125 | J22: =AVERAGE(J3,J8,J15,J20) -> 0.091916667 | P22: Overall Avg | R22: =AVERAGE(R3,R8,R15,R20) -> 0.29225 | S22: =AVERAGE(S3,S8,S15,S20) -> 0.180375 | T22: =AVERAGE(T3,T8,T15,T20) -> 0.10920833 | U22: =AVERAGE(U3,U8,U15,U20) -> 0.30541667
A25: Generalization | F25: Total | G25: Audio | H25: WM | I25: Vocab | J25: Glimpse | L25: Generalization | Q25: Total | R25: Audio | S25: WM | T25: Vocab | U25: Glimpse
E26: k=0 avg | G26: =F27 -> 0.363 | H26: =F28 -> 0.089 | I26: =F29 -> 0.185 | J26: =F30 -> 0.341 | P26: k=0 avg | R26: =Q27 -> 0.375 | S26: =Q28 -> 0.242 | T26: =Q29 -> 0.215 | U26: =Q30 -> 0.633
D27: Audio | F27: 0.363 | H27: =F32-F27 -> 0.106 | I27: =F33-F27 -> 0.124 | J27: =F34-F27 -> 0.281 | O27: Audio | Q27: 0.375 | S27: =Q32-Q27 -> 0.079 | T27: =Q33-Q27 -> 0.088 | U27: =Q34-Q27 -> 0.355
D28: WM | F28: 0.089 | G28: =F32-F28 -> 0.38 | I28: =F35-F28 -> 0.096 | J28: =F36-F28 -> 0.262 | O28: WM | Q28: 0.242 | R28: =Q32-Q28 -> 0.212 | T28: =Q35-Q28 -> 0.036 | U28: =Q36-Q28 -> 0.483
D29: Vocab | F29: 0.185 | G29: =F33-F29 -> 0.302 | H29: =F35-F29 -> 0 | J29: =F37-F29 -> 0.198 | O29: Vocab | Q29: 0.215 | R29: =Q33-Q29 -> 0.248 | S29: =Q35-Q29 -> 0.063 | U29: =Q37-Q29 -> 0.424
D30: Glimpse | F30: 0.341 | G30: =F34-F30 -> 0.303 | H30: =F36-F30 -> 0.01 | I30: =F37-F30 -> 0.042 | O30: Glimpse | Q30: 0.633 | R30: =Q34-Q30 -> 0.097 | S30: =Q36-Q30 -> 0.092 | T30: =Q37-Q30 -> 0.006
E31: k=1 avg | G31: =AVERAGE(G27:G30) -> 0.32833333 | H31: =AVERAGE(H27:H30) -> 0.038666667 | I31: =AVERAGE(I27:I30) -> 0.087333333 | J31: =AVERAGE(J27:J30) -> 0.247 | P31: k=1 avg | R31: =AVERAGE(R27:R30) -> 0.18566667 | S31: =AVERAGE(S27:S30) -> 0.078 | T31: =AVERAGE(T27:T30) -> 0.043333333 | U31: =AVERAGE(U27:U30) -> 0.42066667
C32: Audio | D32: WM | F32: 0.469 | I32: =F39-F32 -> 0.028 | J32: =F40-F32 -> 0.196 | N32: Audio | O32: WM | Q32: 0.454 | T32: =Q39-Q32 -> 0.025 | U32: =Q40-Q32 -> 0.312
C33: Audio | D33: Vocab | F33: 0.487 | H33: =F39-F33 -> 0.01 | J33: =F41-F33 -> 0.179 | N33: Audio | O33: Vocab | Q33: 0.463 | S33: =Q39-Q33 -> 0.016 | U33: =Q41-Q33 -> 0.269
C34: Audio | D34: Glimpse | F34: 0.644 | H34: =F40-F34 -> 0.021 | I34: =F41-F34 -> 0.022 | N34: Audio | O34: Glimpse | Q34: 0.73 | S34: =Q40-Q34 -> 0.036 | T34: =Q41-Q34 -> 0.002
C35: WM | D35: Vocab | F35: 0.185 | G35: =F39-F35 -> 0.312 | J35: =F42-F35 -> 0.201 | N35: WM | O35: Vocab | Q35: 0.278 | R35: =Q39-Q35 -> 0.201 | U35: =Q42-Q35 -> 0.47
C36: WM | D36: Glimpse | F36: 0.351 | G36: =F40-F36 -> 0.314 | I36: =F42-F36 -> 0.035 | N36: WM | O36: Glimpse | Q36: 0.725 | R36: =Q40-Q36 -> 0.041 | T36: =Q42-Q36 -> 0.023
C37: Vocab | D37: Glimpse | F37: 0.383 | G37: =F41-F37 -> 0.283 | H37: =F42-F37 -> 0.003 | N37: Vocab | O37: Glimpse | Q37: 0.639 | R37: =Q41-Q37 -> 0.093 | S37: =Q42-Q37 -> 0.109
E38: k=2 avg | G38: =AVERAGE(G34:G37) -> 0.303 | H38: =AVERAGE(H34:H37) -> 0.012 | I38: =AVERAGE(I34:I37) -> 0.0285 | J38: =AVERAGE(J34:J37) -> 0.201 | P38: k=2 avg | R38: =AVERAGE(R34:R37) -> 0.11166667 | S38: =AVERAGE(S34:S37) -> 0.0725 | T38: =AVERAGE(T34:T37) -> 0.0125 | U38: =AVERAGE(U34:U37) -> 0.47
B39: Audio | C39: WM | D39: Vocab | F39: 0.497 | J39: =F44-F39 -> 0.173 | M39: Audio | N39: WM | O39: Vocab | Q39: 0.479 | U39: =Q44-Q39 -> 0.299
B40: Audio | C40: WM | D40: Glimpse | F40: 0.665 | I40: =F44-F40 -> 0.005 | M40: Audio | N40: WM | O40: Glimpse | Q40: 0.766 | T40: =Q44-Q40 -> 0.012
B41: Audio | C41: Vocab | D41: Glimpse | F41: 0.666 | H41: =F44-F41 -> 0.004 | M41: Audio | N41: Vocab | O41: Glimpse | Q41: 0.732 | S41: =Q44-Q41 -> 0.046
B42: WM | C42: Vocab | D42: Glimpse | F42: 0.386 | G42: =F44-F42 -> 0.284 | M42: WM | N42: Vocab | O42: Glimpse | Q42: 0.748 | R42: =Q44-Q42 -> 0.03
...
